["{\"info\":\"Welcome to the BitMEX Realtime API.\",\"version\":\"2020-12-16T22:50:54.000Z\",\"timestamp\":\"2021-01-04T20:41:44.727Z\",\"docs\":\"https://www.bitmex.com/app/wsAPI\",\"limit\":{\"remaining\":39}}","{\"success\":true,\"subscribe\":\"orderBookL2_25:ETHUSD\",\"request\":{\"op\":\"subscribe\",\"args\":[\"orderBookL2_25:ETHUSD\"]}}","{\"table\":\"orderBookL2_25\",\"action\":\"partial\",\"keys\":[\"symbol\",\"id\",\"side\"],\"types\":{\"symbol\":\"symbol\",\"id\":\"long\",\"side\":\"symbol\",\"size\":\"long\",\"price\":\"float\"},\"foreignKeys\":{\"symbol\":\"instrument\",\"side\":\"side\"},\"attributes\":{\"symbol\":\"parted\",\"id\":\"sorted\"},\"filter\":{\"symbol\":\"ETHUSD\"},\"data\":[{\"symbol\":\"ETHUSD\",\"id\":29699979274,\"side\":\"Sell\",\"size\":174,\"price\":1036.3},{\"symbol\":\"ETHUSD\",\"id\":29699979275,\"side\":\"Sell\",\"size\":11461,\"price\":1036.25},{\"symbol\":\"ETHUSD\",\"id\":29699979276,\"side\":\"Sell\",\"size\":25,\"price\":1036.2},{\"symbol\":\"ETHUSD\",\"id\":29699979281,\"side\":\"Sell\",\"size\":2917,\"price\":1035.95},{\"symbol\":\"ETHUSD\",\"id\":29699979282,\"side\":\"Sell\",\"size\":32,\"price\":1035.9},{\"symbol\":\"ETHUSD\",\"id\":29699979283,\"side\":\"Sell\",\"size\":7095,\"price\":1035.85},{\"symbol\":\"ETHUSD\",\"id\":29699979284,\"side\":\"Sell\",\"size\":987,\"price\":1035.8},{\"symbol\":\"ETHUSD\",\"id\":29699979285,\"side\":\"Sell\",\"size\":683,\"price\":1035.75},{\"symbol\":\"ETHUSD\",\"id\":29699979286,\"side\":\"Sell\",\"size\":29,\"price\":1035.7},{\"symbol\":\"ETHUSD\",\"id\":29699979287,\"side\":\"Sell\",\"size\":28,\"price\":1035.65},{\"symbol\":\"ETHUSD\",\"id\":29699979288,\"side\":\"Sell\",\"size\":28,\"price\":1035.6},{\"symbol\":\"ETHUSD\",\"id\":29699979289,\"side\":\"Sell\",\"size\":347,\"price\":1035.55},{\"symbol\":\"ETHUSD\",\"id\":29699979290,\"side\":\"Sell\",\"size\":33,\"price\":1035.5},{\"symbol\":\"ETHUSD\",\"id\":29699979291,\"side\":\"Sell\",\"size\":30,\"price\":1035.45},{\"symbol\":\"ETHUSD\",\"id\":29699979292,\"side\":\"Sell\",\"size\":33,\"price\":1035.4},{\"symbol\":\"ETHUSD\",\"id\":29699979293,\"side\":\"Sell\",\"size\":32,\"price\":1035.35},{\"symbol\":\"ETHUSD\",\"id\":29699979294,\"side\":\"Sell\",\"size\":31,\"price\":1035.3},{\"symbol\":\"ETHUSD\",\"id\":29699979295,\"side\":\"Sell\",\"size\":33,\"price\":1035.25},{\"symbol\":\"ETHUSD\",\"id\":29699979296,\"side\":\"Sell\",\"size\":32,\"price\":1035.2},{\"symbol\":\"ETHUSD\",\"id\":29699979297,\"side\":\"Sell\",\"size\":28,\"price\":1035.15},{\"symbol\":\"ETHUSD\",\"id\":29699979298,\"side\":\"Sell\",\"size\":31,\"price\":1035.1},{\"symbol\":\"ETHUSD\",\"id\":29699979299,\"side\":\"Sell\",\"size\":28,\"price\":1035.05},{\"symbol\":\"ETHUSD\",\"id\":29699979300,\"side\":\"Sell\",\"size\":30,\"price\":1035},{\"symbol\":\"ETHUSD\",\"id\":29699979301,\"side\":\"Sell\",\"size\":30,\"price\":1034.95},{\"symbol\":\"ETHUSD\",\"id\":29699979302,\"side\":\"Sell\",\"size\":1077,\"price\":1034.9},{\"symbol\":\"ETHUSD\",\"id\":29699979303,\"side\":\"Buy\",\"size\":7000,\"price\":1034.85},{\"symbol\":\"ETHUSD\",\"id\":29699979305,\"side\":\"Buy\",\"size\":407,\"price\":1034.75},{\"symbol\":\"ETHUSD\",\"id\":29699979307,\"side\":\"Buy\",\"size\":2203,\"price\":1034.65},{\"symbol\":\"ETHUSD\",\"id\":29699979311,\"side\":\"Buy\",\"size\":29,\"price\":1034.45},{\"symbol\":\"ETHUSD\",\"id\":29699979312,\"side\":\"Buy\",\"size\":32,\"price\":1034.4},{\"symbol\":\"ETHUSD\",\"id\":29699979313,\"side\":\"Buy\",\"size\":92,\"price\":1034.35},{\"symbol\":\"ETHUSD\",\"id\":29699979314,\"side\":\"Buy\",\"size\":28,\"price\":1034.3},{\"symbol\":\"ETHUSD\",\"id\":29699979315,\"side\":\"Buy\",\"size\":39,\"price\":1034.25},{\"symbol\":\"ETHUSD\",\"id\":29699979316,\"side\":\"Buy\",\"size\":34,\"price\":1034.2},{\"symbol\":\"ETHUSD\",\"id\":29699979317,\"side\":\"Buy\",\"size\":80,\"price\":1034.15},{\"symbol\":\"ETHUSD\",\"id\":29699979318,\"side\":\"Buy\",\"size\":81,\"price\":1034.1},{\"symbol\":\"ETHUSD\",\"id\":29699979319,\"side\":\"Buy\",\"size\":81,\"price\":1034.05},{\"symbol\":\"ETHUSD\",\"id\":29699979320,\"side\":\"Buy\",\"size\":83,\"price\":1034},{\"symbol\":\"ETHUSD\",\"id\":29699979321,\"side\":\"Buy\",\"size\":82,\"price\":1033.95},{\"symbol\":\"ETHUSD\",\"id\":29699979322,\"side\":\"Buy\",\"size\":6489,\"price\":1033.9},{\"symbol\":\"ETHUSD\",\"id\":29699979323,\"side\":\"Buy\",\"size\":79,\"price\":1033.85},{\"symbol\":\"ETHUSD\",\"id\":29699979324,\"side\":\"Buy\",\"size\":82,\"price\":1033.8},{\"symbol\":\"ETHUSD\",\"id\":29699979325,\"side\":\"Buy\",\"size\":89,\"price\":1033.75},{\"symbol\":\"ETHUSD\",\"id\":29699979326,\"side\":\"Buy\",\"size\":79,\"price\":1033.7},{\"symbol\":\"ETHUSD\",\"id\":29699979327,\"side\":\"Buy\",\"size\":15423,\"price\":1033.65},{\"symbol\":\"ETHUSD\",\"id\":29699979328,\"side\":\"Buy\",\"size\":8228,\"price\":1033.6},{\"symbol\":\"ETHUSD\",\"id\":29699979329,\"side\":\"Buy\",\"size\":34,\"price\":1033.55},{\"symbol\":\"ETHUSD\",\"id\":29699979330,\"side\":\"Buy\",\"size\":10028,\"price\":1033.5},{\"symbol\":\"ETHUSD\",\"id\":29699979331,\"side\":\"Buy\",\"size\":33,\"price\":1033.45},{\"symbol\":\"ETHUSD\",\"id\":29699979332,\"side\":\"Buy\",\"size\":805,\"price\":1033.4}]}","{\"table\":\"orderBookL2_25\",\"action\":\"delete\",\"data\":[{\"symbol\":\"ETHUSD\",\"id\":29699979305,\"side\":\"Buy\"}]}","{\"table\":\"orderBookL2_25\",\"action\":\"update\",\"data\":[{\"symbol\":\"ETHUSD\",\"id\":29699979302,\"side\":\"Sell\",\"size\":1170}]}","{\"table\":\"orderBookL2_25\",\"action\":\"insert\",\"data\":[{\"symbol\":\"ETHUSD\",\"id\":29699979334,\"side\":\"Buy\",\"size\":278,\"price\":1033.3}]}","{\"table\":\"orderBookL2_25\",\"action\":\"update\",\"data\":[{\"symbol\":\"ETHUSD\",\"id\":29699979302,\"side\":\"Sell\",\"size\":1270}]}","{\"table\":\"orderBookL2_25\",\"action\":\"update\",\"data\":[{\"symbol\":\"ETHUSD\",\"id\":29699979302,\"side\":\"Sell\",\"size\":1170}]}","{\"table\":\"orderBookL2_25\",\"action\":\"update\",\"data\":[{\"symbol\":\"ETHUSD\",\"id\":29699979302,\"side\":\"Sell\",\"size\":1270}]}","{\"table\":\"orderBookL2_25\",\"action\":\"update\",\"data\":[{\"symbol\":\"ETHUSD\",\"id\":29699979300,\"side\":\"Sell\",\"size\":2030}]}","{\"table\":\"orderBookL2_25\",\"action\":\"delete\",\"data\":[{\"symbol\":\"ETHUSD\",\"id\":29699979311,\"side\":\"Buy\"},{\"symbol\":\"ETHUSD\",\"id\":29699979312,\"side\":\"Buy\"}]}","{\"table\":\"orderBookL2_25\",\"action\":\"update\",\"data\":[{\"symbol\":\"ETHUSD\",\"id\":29699979302,\"side\":\"Sell\",\"size\":804},{\"symbol\":\"ETHUSD\",\"id\":29699979313,\"side\":\"Buy\",\"size\":93},{\"symbol\":\"ETHUSD\",\"id\":29699979332,\"side\":\"Buy\",\"size\":802}]}","{\"table\":\"orderBookL2_25\",\"action\":\"insert\",\"data\":[{\"symbol\":\"ETHUSD\",\"id\":29699979333,\"side\":\"Buy\",\"size\":33,\"price\":1033.35},{\"symbol\":\"ETHUSD\",\"id\":29699979335,\"side\":\"Buy\",\"size\":7171,\"price\":1033.25}]}","{\"table\":\"orderBookL2_25\",\"action\":\"update\",\"data\":[{\"symbol\":\"ETHUSD\",\"id\":29699979302,\"side\":\"Sell\",\"size\":1370}]}","{\"table\":\"orderBookL2_25\",\"action\":\"delete\",\"data\":[{\"symbol\":\"ETHUSD\",\"id\":29699979334,\"side\":\"Buy\"}]}","{\"table\":\"orderBookL2_25\",\"action\":\"update\",\"data\":[{\"symbol\":\"ETHUSD\",\"id\":29699979313,\"side\":\"Buy\",\"size\":33}]}","{\"table\":\"orderBookL2_25\",\"action\":\"insert\",\"data\":[{\"symbol\":\"ETHUSD\",\"id\":29699979337,\"side\":\"Buy\",\"size\":300,\"price\":1033.15}]}","{\"table\":\"orderBookL2_25\",\"action\":\"update\",\"data\":[{\"symbol\":\"ETHUSD\",\"id\":29699979302,\"side\":\"Sell\",\"size\":1520}]}","{\"table\":\"orderBookL2_25\",\"action\":\"delete\",\"data\":[{\"symbol\":\"ETHUSD\",\"id\":29699979303,\"side\":\"Buy\"}]}","{\"table\":\"orderBookL2_25\",\"action\":\"update\",\"data\":[{\"symbol\":\"ETHUSD\",\"id\":29699979283,\"side\":\"Sell\",\"size\":7028},{\"symbol\":\"ETHUSD\",\"id\":29699979302,\"side\":\"Sell\",\"size\":1587}]}","{\"table\":\"orderBookL2_25\",\"action\":\"insert\",\"data\":[{\"symbol\":\"ETHUSD\",\"id\":29699979338,\"side\":\"Buy\",\"size\":10101,\"price\":1033.1}]}","{\"table\":\"orderBookL2_25\",\"action\":\"delete\",\"data\":[{\"symbol\":\"ETHUSD\",\"id\":29699979274,\"side\":\"Sell\"},{\"symbol\":\"ETHUSD\",\"id\":29699979275,\"side\":\"Sell\"},{\"symbol\":\"ETHUSD\",\"id\":29699979282,\"side\":\"Sell\"},{\"symbol\":\"ETHUSD\",\"id\":29699979313,\"side\":\"Buy\"}]}","{\"table\":\"orderBookL2_25\",\"action\":\"update\",\"data\":[{\"symbol\":\"ETHUSD\",\"id\":29699979283,\"side\":\"Sell\",\"size\":7000},{\"symbol\":\"ETHUSD\",\"id\":29699979284,\"side\":\"Sell\",\"size\":955},{\"symbol\":\"ETHUSD\",\"id\":29699979300,\"side\":\"Sell\",\"size\":30},{\"symbol\":\"ETHUSD\",\"id\":29699979302,\"side\":\"Sell\",\"size\":300}]}","{\"table\":\"orderBookL2_25\",\"action\":\"insert\",\"data\":[{\"symbol\":\"ETHUSD\",\"id\":29699979303,\"side\":\"Sell\",\"size\":2029,\"price\":1034.85},{\"symbol\":\"ETHUSD\",\"id\":29699979304,\"side\":\"Sell\",\"size\":93,\"price\":1034.8},{\"symbol\":\"ETHUSD\",\"id\":29699979306,\"side\":\"Sell\",\"size\":1152,\"price\":1034.7},{\"symbol\":\"ETHUSD\",\"id\":29699979339,\"side\":\"Buy\",\"size\":332,\"price\":1033.05}]}","{\"table\":\"orderBookL2_25\",\"action\":\"update\",\"data\":[{\"symbol\":\"ETHUSD\",\"id\":29699979291,\"side\":\"Sell\",\"size\":153},{\"symbol\":\"ETHUSD\",\"id\":29699979306,\"side\":\"Sell\",\"size\":1151}]}","{\"table\":\"orderBookL2_25\",\"action\":\"update\",\"data\":[{\"symbol\":\"ETHUSD\",\"id\":29699979302,\"side\":\"Sell\",\"size\":233},{\"symbol\":\"ETHUSD\",\"id\":29699979303,\"side\":\"Sell\",\"size\":2096},{\"symbol\":\"ETHUSD\",\"id\":29699979306,\"side\":\"Sell\",\"size\":1076}]}","{\"table\":\"orderBookL2_25\",\"action\":\"delete\",\"data\":[{\"symbol\":\"ETHUSD\",\"id\":29699979276,\"side\":\"Sell\"}]}","{\"table\":\"orderBookL2_25\",\"action\":\"update\",\"data\":[{\"symbol\":\"ETHUSD\",\"id\":29699979302,\"side\":\"Sell\",\"size\":33},{\"symbol\":\"ETHUSD\",\"id\":29699979304,\"side\":\"Sell\",\"size\":125},{\"symbol\":\"ETHUSD\",\"id\":29699979330,\"side\":\"Buy\",\"size\":10078},{\"symbol\":\"ETHUSD\",\"id\":29699979331,\"side\":\"Buy\",\"size\":83}]}","{\"table\":\"orderBookL2_25\",\"action\":\"insert\",\"data\":[{\"symbol\":\"ETHUSD\",\"id\":29699979305,\"side\":\"Sell\",\"size\":29,\"price\":1034.75}]}","{\"table\":\"orderBookL2_25\",\"action\":\"update\",\"data\":[{\"symbol\":\"ETHUSD\",\"id\":29699979303,\"side\":\"Sell\",\"size\":96},{\"symbol\":\"ETHUSD\",\"id\":29699979304,\"side\":\"Sell\",\"size\":32},{\"symbol\":\"ETHUSD\",\"id\":29699979306,\"side\":\"Sell\",\"size\":1169}]}","{\"table\":\"orderBookL2_25\",\"action\":\"update\",\"data\":[{\"symbol\":\"ETHUSD\",\"id\":29699979306,\"side\":\"Sell\",\"size\":554},{\"symbol\":\"ETHUSD\",\"id\":29699979338,\"side\":\"Buy\",\"size\":10125}]}","{\"table\":\"orderBookL2_25\",\"action\":\"delete\",\"data\":[{\"symbol\":\"ETHUSD\",\"id\":29699979339,\"side\":\"Buy\"}]}","{\"table\":\"orderBookL2_25\",\"action\":\"update\",\"data\":[{\"symbol\":\"ETHUSD\",\"id\":29699979306,\"side\":\"Sell\",\"size\":93},{\"symbol\":\"ETHUSD\",\"id\":29699979307,\"side\":\"Buy\",\"size\":9203},{\"symbol\":\"ETHUSD\",\"id\":29699979315,\"side\":\"Buy\",\"size\":100}]}","{\"table\":\"orderBookL2_25\",\"action\":\"insert\",\"data\":[{\"symbol\":\"ETHUSD\",\"id\":29699979310,\"side\":\"Buy\",\"size\":2000,\"price\":1034.5}]}","{\"table\":\"orderBookL2_25\",\"action\":\"update\",\"data\":[{\"symbol\":\"ETHUSD\",\"id\":29699979291,\"side\":\"Sell\",\"size\":30},{\"symbol\":\"ETHUSD\",\"id\":29699979307,\"side\":\"Buy\",\"size\":9303}]}","{\"table\":\"orderBookL2_25\",\"action\":\"delete\",\"data\":[{\"symbol\":\"ETHUSD\",\"id\":29699979338,\"side\":\"Buy\"}]}","{\"table\":\"orderBookL2_25\",\"action\":\"update\",\"data\":[{\"symbol\":\"ETHUSD\",\"id\":29699979288,\"side\":\"Sell\",\"size\":95},{\"symbol\":\"ETHUSD\",\"id\":29699979303,\"side\":\"Sell\",\"size\":29},{\"symbol\":\"ETHUSD\",\"id\":29699979307,\"side\":\"Buy\",\"size\":9663}]}","{\"table\":\"orderBookL2_25\",\"action\":\"insert\",\"data\":[{\"symbol\":\"ETHUSD\",\"id\":29699979336,\"side\":\"Buy\",\"size\":278,\"price\":1033.2}]}","{\"table\":\"orderBookL2_25\",\"action\":\"delete\",\"data\":[{\"symbol\":\"ETHUSD\",\"id\":29699979284,\"side\":\"Sell\"},{\"symbol\":\"ETHUSD\",\"id\":29699979304,\"side\":\"Sell\"},{\"symbol\":\"ETHUSD\",\"id\":29699979305,\"side\":\"Sell\"},{\"symbol\":\"ETHUSD\",\"id\":29699979306,\"side\":\"Sell\"},{\"symbol\":\"ETHUSD\",\"id\":29699979310,\"side\":\"Buy\"},{\"symbol\":\"ETHUSD\",\"id\":29699979335,\"side\":\"Buy\"},{\"symbol\":\"ETHUSD\",\"id\":29699979336,\"side\":\"Buy\"},{\"symbol\":\"ETHUSD\",\"id\":29699979337,\"side\":\"Buy\"}]}","{\"table\":\"orderBookL2_25\",\"action\":\"update\",\"data\":[{\"symbol\":\"ETHUSD\",\"id\":29699979307,\"side\":\"Buy\",\"size\":11403},{\"symbol\":\"ETHUSD\",\"id\":29699979316,\"side\":\"Buy\",\"size\":989}]}","{\"table\":\"orderBookL2_25\",\"action\":\"insert\",\"data\":[{\"symbol\":\"ETHUSD\",\"id\":29699979272,\"side\":\"Sell\",\"size\":213,\"price\":1036.4},{\"symbol\":\"ETHUSD\",\"id\":29699979274,\"side\":\"Sell\",\"size\":174,\"price\":1036.3},{\"symbol\":\"ETHUSD\",\"id\":29699979275,\"side\":\"Sell\",\"size\":11461,\"price\":1036.25},{\"symbol\":\"ETHUSD\",\"id\":29699979276,\"side\":\"Sell\",\"size\":25,\"price\":1036.2},{\"symbol\":\"ETHUSD\",\"id\":29699979305,\"side\":\"Buy\",\"size\":7029,\"price\":1034.75},{\"symbol\":\"ETHUSD\",\"id\":29699979306,\"side\":\"Buy\",\"size\":7000,\"price\":1034.7},{\"symbol\":\"ETHUSD\",\"id\":29699979312,\"side\":\"Buy\",\"size\":955,\"price\":1034.4},{\"symbol\":\"ETHUSD\",\"id\":29699979334,\"side\":\"Buy\",\"size\":278,\"price\":1033.3}]}","{\"table\":\"orderBookL2_25\",\"action\":\"delete\",\"data\":[{\"symbol\":\"ETHUSD\",\"id\":29699979272,\"side\":\"Sell\"},{\"symbol\":\"ETHUSD\",\"id\":29699979329,\"side\":\"Buy\"},{\"symbol\":\"ETHUSD\",\"id\":29699979330,\"side\":\"Buy\"},{\"symbol\":\"ETHUSD\",\"id\":29699979331,\"side\":\"Buy\"},{\"symbol\":\"ETHUSD\",\"id\":29699979332,\"side\":\"Buy\"},{\"symbol\":\"ETHUSD\",\"id\":29699979333,\"side\":\"Buy\"},{\"symbol\":\"ETHUSD\",\"id\":29699979334,\"side\":\"Buy\"}]}","{\"table\":\"orderBookL2_25\",\"action\":\"update\",\"data\":[{\"symbol\":\"ETHUSD\",\"id\":29699979305,\"side\":\"Buy\",\"size\":7079},{\"symbol\":\"ETHUSD\",\"id\":29699979307,\"side\":\"Buy\",\"size\":9403},{\"symbol\":\"ETHUSD\",\"id\":29699979312,\"side\":\"Buy\",\"size\":33},{\"symbol\":\"ETHUSD\",\"id\":29699979316,\"side\":\"Buy\",\"size\":34},{\"symbol\":\"ETHUSD\",\"id\":29699979321,\"side\":\"Buy\",\"size\":10082},{\"symbol\":\"ETHUSD\",\"id\":29699979328,\"side\":\"Buy\",\"size\":8200}]}","{\"table\":\"orderBookL2_25\",\"action\":\"insert\",\"data\":[{\"symbol\":\"ETHUSD\",\"id\":29699979284,\"side\":\"Sell\",\"size\":32,\"price\":1035.8},{\"symbol\":\"ETHUSD\",\"id\":29699979304,\"side\":\"Buy\",\"size\":2075,\"price\":1034.8},{\"symbol\":\"ETHUSD\",\"id\":29699979308,\"side\":\"Buy\",\"size\":31,\"price\":1034.6},{\"symbol\":\"ETHUSD\",\"id\":29699979309,\"side\":\"Buy\",\"size\":32,\"price\":1034.55},{\"symbol\":\"ETHUSD\",\"id\":29699979310,\"side\":\"Buy\",\"size\":30,\"price\":1034.5},{\"symbol\":\"ETHUSD\",\"id\":29699979311,\"side\":\"Buy\",\"size\":29,\"price\":1034.45},{\"symbol\":\"ETHUSD\",\"id\":29699979313,\"side\":\"Buy\",\"size\":30,\"price\":1034.35}]}","{\"table\":\"orderBookL2_25\",\"action\":\"delete\",\"data\":[{\"symbol\":\"ETHUSD\",\"id\":29699979274,\"side\":\"Sell\"}]}","{\"table\":\"orderBookL2_25\",\"action\":\"update\",\"data\":[{\"symbol\":\"ETHUSD\",\"id\":29699979285,\"side\":\"Sell\",\"size\":350},{\"symbol\":\"ETHUSD\",\"id\":29699979304,\"side\":\"Buy\",\"size\":9435}]}","{\"table\":\"orderBookL2_25\",\"action\":\"insert\",\"data\":[{\"symbol\":\"ETHUSD\",\"id\":29699979280,\"side\":\"Sell\",\"size\":333,\"price\":1036}]}","{\"table\":\"orderBookL2_25\",\"action\":\"update\",\"data\":[{\"symbol\":\"ETHUSD\",\"id\":29699979304,\"side\":\"Buy\",\"size\":9275},{\"symbol\":\"ETHUSD\",\"id\":29699979307,\"side\":\"Buy\",\"size\":9203}]}","{\"table\":\"orderBookL2_25\",\"action\":\"delete\",\"data\":[{\"symbol\":\"ETHUSD\",\"id\":29699979308,\"side\":\"Buy\"},{\"symbol\":\"ETHUSD\",\"id\":29699979309,\"side\":\"Buy\"},{\"symbol\":\"ETHUSD\",\"id\":29699979310,\"side\":\"Buy\"}]}","{\"table\":\"orderBookL2_25\",\"action\":\"update\",\"data\":[{\"symbol\":\"ETHUSD\",\"id\":29699979303,\"side\":\"Sell\",\"size\":490},{\"symbol\":\"ETHUSD\",\"id\":29699979304,\"side\":\"Buy\",\"size\":9075},{\"symbol\":\"ETHUSD\",\"id\":29699979325,\"side\":\"Buy\",\"size\":367},{\"symbol\":\"ETHUSD\",\"id\":29699979328,\"side\":\"Buy\",\"size\":8283}]}","{\"table\":\"orderBookL2_25\",\"action\":\"insert\",\"data\":[{\"symbol\":\"ETHUSD\",\"id\":29699979329,\"side\":\"Buy\",\"size\":306,\"price\":1033.55},{\"symbol\":\"ETHUSD\",\"id\":29699979330,\"side\":\"Buy\",\"size\":79,\"price\":1033.5},{\"symbol\":\"ETHUSD\",\"id\":29699979331,\"side\":\"Buy\",\"size\":348,\"price\":1033.45}]}","{\"table\":\"orderBookL2_25\",\"action\":\"update\",\"data\":[{\"symbol\":\"ETHUSD\",\"id\":29699979304,\"side\":\"Buy\",\"size\":7575},{\"symbol\":\"ETHUSD\",\"id\":29699979305,\"side\":\"Buy\",\"size\":9079},{\"symbol\":\"ETHUSD\",\"id\":29699979325,\"side\":\"Buy\",\"size\":89},{\"symbol\":\"ETHUSD\",\"id\":29699979329,\"side\":\"Buy\",\"size\":28},{\"symbol\":\"ETHUSD\",\"id\":29699979331,\"side\":\"Buy\",\"size\":377}]}","{\"table\":\"orderBookL2_25\",\"action\":\"update\",\"data\":[{\"symbol\":\"ETHUSD\",\"id\":29699979331,\"side\":\"Buy\",\"size\":655}]}","{\"table\":\"orderBookL2_25\",\"action\":\"update\",\"data\":[{\"symbol\":\"ETHUSD\",\"id\":29699979293,\"side\":\"Sell\",\"size\":93},{\"symbol\":\"ETHUSD\",\"id\":29699979315,\"side\":\"Buy\",\"size\":39}]}","{\"table\":\"orderBookL2_25\",\"action\":\"update\",\"data\":[{\"symbol\":\"ETHUSD\",\"id\":29699979305,\"side\":\"Buy\",\"size\":7079}]}","{\"table\":\"orderBookL2_25\",\"action\":\"update\",\"data\":[{\"symbol\":\"ETHUSD\",\"id\":29699979305,\"side\":\"Buy\",\"size\":9079}]}","{\"table\":\"orderBookL2_25\",\"action\":\"update\",\"data\":[{\"symbol\":\"ETHUSD\",\"id\":29699979293,\"side\":\"Sell\",\"size\":32},{\"symbol\":\"ETHUSD\",\"id\":29699979305,\"side\":\"Buy\",\"size\":7079},{\"symbol\":\"ETHUSD\",\"id\":29699979320,\"side\":\"Buy\",\"size\":283}]}","{\"table\":\"orderBookL2_25\",\"action\":\"update\",\"data\":[{\"symbol\":\"ETHUSD\",\"id\":29699979305,\"side\":\"Buy\",\"size\":9079}]}","{\"table\":\"orderBookL2_25\",\"action\":\"delete\",\"data\":[{\"symbol\":\"ETHUSD\",\"id\":29699979331,\"side\":\"Buy\"}]}","{\"table\":\"orderBookL2_25\",\"action\":\"update\",\"data\":[{\"symbol\":\"ETHUSD\",\"id\":29699979304,\"side\":\"Buy\",\"size\":7675}]}","{\"table\":\"orderBookL2_25\",\"action\":\"insert\",\"data\":[{\"symbol\":\"ETHUSD\",\"id\":29699979310,\"side\":\"Buy\",\"size\":33,\"price\":1034.5}]}","{\"table\":\"orderBookL2_25\",\"action\":\"delete\",\"data\":[{\"symbol\":\"ETHUSD\",\"id\":29699979303,\"side\":\"Sell\"},{\"symbol\":\"ETHUSD\",\"id\":29699979329,\"side\":\"Buy\"},{\"symbol\":\"ETHUSD\",\"id\":29699979330,\"side\":\"Buy\"}]}","{\"table\":\"orderBookL2_25\",\"action\":\"update\",\"data\":[{\"symbol\":\"ETHUSD\",\"id\":29699979304,\"side\":\"Buy\",\"size\":8120},{\"symbol\":\"ETHUSD\",\"id\":29699979305,\"side\":\"Buy\",\"size\":7000},{\"symbol\":\"ETHUSD\",\"id\":29699979318,\"side\":\"Buy\",\"size\":1036}]}","{\"table\":\"orderBookL2_25\",\"action\":\"insert\",\"data\":[{\"symbol\":\"ETHUSD\",\"id\":29699979274,\"side\":\"Sell\",\"size\":174,\"price\":1036.3},{\"symbol\":\"ETHUSD\",\"id\":29699979303,\"side\":\"Buy\",\"size\":2990,\"price\":1034.85},{\"symbol\":\"ETHUSD\",\"id\":29699979309,\"side\":\"Buy\",\"size\":28,\"price\":1034.55}]}","{\"table\":\"orderBookL2_25\",\"action\":\"delete\",\"data\":[{\"symbol\":\"ETHUSD\",\"id\":29699979302,\"side\":\"Sell\"},{\"symbol\":\"ETHUSD\",\"id\":29699979328,\"side\":\"Buy\"}]}","{\"table\":\"orderBookL2_25\",\"action\":\"update\",\"data\":[{\"symbol\":\"ETHUSD\",\"id\":29699979303,\"side\":\"Buy\",\"size\":9740},{\"symbol\":\"ETHUSD\",\"id\":29699979304,\"side\":\"Buy\",\"size\":7100},{\"symbol\":\"ETHUSD\",\"id\":29699979318,\"side\":\"Buy\",\"size\":81},{\"symbol\":\"ETHUSD\",\"id\":29699979326,\"side\":\"Buy\",\"size\":50},{\"symbol\":\"ETHUSD\",\"id\":29699979327,\"side\":\"Buy\",\"size\":15393}]}","{\"table\":\"orderBookL2_25\",\"action\":\"insert\",\"data\":[{\"symbol\":\"ETHUSD\",\"id\":29699979272,\"side\":\"Sell\",\"size\":213,\"price\":1036.4},{\"symbol\":\"ETHUSD\",\"id\":29699979302,\"side\":\"Buy\",\"size\":500,\"price\":1034.9}]}","{\"table\":\"orderBookL2_25\",\"action\":\"update\",\"data\":[{\"symbol\":\"ETHUSD\",\"id\":29699979302,\"side\":\"Buy\",\"size\":9500},{\"symbol\":\"ETHUSD\",\"id\":29699979303,\"side\":\"Buy\",\"size\":7490},{\"symbol\":\"ETHUSD\",\"id\":29699979307,\"side\":\"Buy\",\"size\":2203},{\"symbol\":\"ETHUSD\",\"id\":29699979325,\"side\":\"Buy\",\"size\":367}]}","{\"table\":\"orderBookL2_25\",\"action\":\"update\",\"data\":[{\"symbol\":\"ETHUSD\",\"id\":29699979304,\"side\":\"Buy\",\"size\":7000}]}","{\"table\":\"orderBookL2_25\",\"action\":\"update\",\"data\":[{\"symbol\":\"ETHUSD\",\"id\":29699979311,\"side\":\"Buy\",\"size\":89}]}","{\"table\":\"orderBookL2_25\",\"action\":\"update\",\"data\":[{\"symbol\":\"ETHUSD\",\"id\":29699979302,\"side\":\"Buy\",\"size\":9600}]}","{\"table\":\"orderBookL2_25\",\"action\":\"update\",\"data\":[{\"symbol\":\"ETHUSD\",\"id\":29699979301,\"side\":\"Sell\",\"size\":491},{\"symbol\":\"ETHUSD\",\"id\":29699979325,\"side\":\"Buy\",\"size\":89}]}","{\"table\":\"orderBookL2_25\",\"action\":\"update\",\"data\":[{\"symbol\":\"ETHUSD\",\"id\":29699979286,\"side\":\"Sell\",\"size\":1848},{\"symbol\":\"ETHUSD\",\"id\":29699979322,\"side\":\"Buy\",\"size\":7444}]}","{\"table\":\"orderBookL2_25\",\"action\":\"delete\",\"data\":[{\"symbol\":\"ETHUSD\",\"id\":29699979272,\"side\":\"Sell\"},{\"symbol\":\"ETHUSD\",\"id\":29699979327,\"side\":\"Buy\"}]}","{\"table\":\"orderBookL2_25\",\"action\":\"update\",\"data\":[{\"symbol\":\"ETHUSD\",\"id\":29699979281,\"side\":\"Sell\",\"size\":2950},{\"symbol\":\"ETHUSD\",\"id\":29699979283,\"side\":\"Sell\",\"size\":7028},{\"symbol\":\"ETHUSD\",\"id\":29699979301,\"side\":\"Sell\",\"size\":30},{\"symbol\":\"ETHUSD\",\"id\":29699979307,\"side\":\"Buy\",\"size\":2234},{\"symbol\":\"ETHUSD\",\"id\":29699979326,\"side\":\"Buy\",\"size\":81}]}","{\"table\":\"orderBookL2_25\",\"action\":\"insert\",\"data\":[{\"symbol\":\"ETHUSD\",\"id\":29699979282,\"side\":\"Sell\",\"size\":30,\"price\":1035.9},{\"symbol\":\"ETHUSD\",\"id\":29699979308,\"side\":\"Buy\",\"size\":30,\"price\":1034.6}]}","{\"table\":\"orderBookL2_25\",\"action\":\"update\",\"data\":[{\"symbol\":\"ETHUSD\",\"id\":29699979302,\"side\":\"Buy\",\"size\":9500},{\"symbol\":\"ETHUSD\",\"id\":29699979303,\"side\":\"Buy\",\"size\":7000}]}","{\"table\":\"orderBookL2_25\",\"action\":\"update\",\"data\":[{\"symbol\":\"ETHUSD\",\"id\":29699979302,\"side\":\"Buy\",\"size\":9700}]}","{\"table\":\"orderBookL2_25\",\"action\":\"delete\",\"data\":[{\"symbol\":\"ETHUSD\",\"id\":29699979301,\"side\":\"Sell\"},{\"symbol\":\"ETHUSD\",\"id\":29699979326,\"side\":\"Buy\"}]}","{\"table\":\"orderBookL2_25\",\"action\":\"update\",\"data\":[{\"symbol\":\"ETHUSD\",\"id\":29699979286,\"side\":\"Sell\",\"size\":1908},{\"symbol\":\"ETHUSD\",\"id\":29699979302,\"side\":\"Buy\",\"size\":9560}]}","{\"table\":\"orderBookL2_25\",\"action\":\"insert\",\"data\":[{\"symbol\":\"ETHUSD\",\"id\":29699979272,\"side\":\"Sell\",\"size\":213,\"price\":1036.4},{\"symbol\":\"ETHUSD\",\"id\":29699979301,\"side\":\"Buy\",\"size\":500,\"price\":1034.95}]}","{\"table\":\"orderBookL2_25\",\"action\":\"delete\",\"data\":[{\"symbol\":\"ETHUSD\",\"id\":29699979280,\"side\":\"Sell\"},{\"symbol\":\"ETHUSD\",\"id\":29699979294,\"side\":\"Sell\"},{\"symbol\":\"ETHUSD\",\"id\":29699979295,\"side\":\"Sell\"},{\"symbol\":\"ETHUSD\",\"id\":29699979296,\"side\":\"Sell\"},{\"symbol\":\"ETHUSD\",\"id\":29699979297,\"side\":\"Sell\"},{\"symbol\":\"ETHUSD\",\"id\":29699979298,\"side\":\"Sell\"},{\"symbol\":\"ETHUSD\",\"id\":29699979299,\"side\":\"Sell\"},{\"symbol\":\"ETHUSD\",\"id\":29699979300,\"side\":\"Sell\"},{\"symbol\":\"ETHUSD\",\"id\":29699979306,\"side\":\"Buy\"}]}","{\"table\":\"orderBookL2_25\",\"action\":\"update\",\"data\":[{\"symbol\":\"ETHUSD\",\"id\":29699979275,\"side\":\"Sell\",\"size\":11794},{\"symbol\":\"ETHUSD\",\"id\":29699979283,\"side\":\"Sell\",\"size\":28},{\"symbol\":\"ETHUSD\",\"id\":29699979286,\"side\":\"Sell\",\"size\":1848},{\"symbol\":\"ETHUSD\",\"id\":29699979301,\"side\":\"Buy\",\"size\":10030},{\"symbol\":\"ETHUSD\",\"id\":29699979302,\"side\":\"Buy\",\"size\":9200},{\"symbol\":\"ETHUSD\",\"id\":29699979304,\"side\":\"Buy\",\"size\":7011},{\"symbol\":\"ETHUSD\",\"id\":29699979307,\"side\":\"Buy\",\"size\":31},{\"symbol\":\"ETHUSD\",\"id\":29699979309,\"side\":\"Buy\",\"size\":15028},{\"symbol\":\"ETHUSD\",\"id\":29699979321,\"side\":\"Buy\",\"size\":10050},{\"symbol\":\"ETHUSD\",\"id\":29699979322,\"side\":\"Buy\",\"size\":7413},{\"symbol\":\"ETHUSD\",\"id\":29699979323,\"side\":\"Buy\",\"size\":50},{\"symbol\":\"ETHUSD\",\"id\":29699979324,\"side\":\"Buy\",\"size\":50},{\"symbol\":\"ETHUSD\",\"id\":29699979325,\"side\":\"Buy\",\"size\":61}]}","{\"table\":\"orderBookL2_25\",\"action\":\"insert\",\"data\":[{\"symbol\":\"ETHUSD\",\"id\":29699979263,\"side\":\"Sell\",\"size\":4,\"price\":1036.85},{\"symbol\":\"ETHUSD\",\"id\":29699979265,\"side\":\"Sell\",\"size\":836,\"price\":1036.75},{\"symbol\":\"ETHUSD\",\"id\":29699979266,\"side\":\"Sell\",\"size\":6160,\"price\":1036.7},{\"symbol\":\"ETHUSD\",\"id\":29699979267,\"side\":\"Sell\",\"size\":45,\"price\":1036.65},{\"symbol\":\"ETHUSD\",\"id\":29699979268,\"side\":\"Sell\",\"size\":428,\"price\":1036.6},{\"symbol\":\"ETHUSD\",\"id\":29699979269,\"side\":\"Sell\",\"size\":349,\"price\":1036.55},{\"symbol\":\"ETHUSD\",\"id\":29699979270,\"side\":\"Sell\",\"size\":21,\"price\":1036.5},{\"symbol\":\"ETHUSD\",\"id\":29699979271,\"side\":\"Sell\",\"size\":11,\"price\":1036.45},{\"symbol\":\"ETHUSD\",\"id\":29699979326,\"side\":\"Buy\",\"size\":50,\"price\":1033.7}]}","{\"table\":\"orderBookL2_25\",\"action\":\"delete\",\"data\":[{\"symbol\":\"ETHUSD\",\"id\":29699979291,\"side\":\"Sell\"},{\"symbol\":\"ETHUSD\",\"id\":29699979292,\"side\":\"Sell\"},{\"symbol\":\"ETHUSD\",\"id\":29699979293,\"side\":\"Sell\"}]}","{\"table\":\"orderBookL2_25\",\"action\":\"update\",\"data\":[{\"symbol\":\"ETHUSD\",\"id\":29699979266,\"side\":\"Sell\",\"size\":55},{\"symbol\":\"ETHUSD\",\"id\":29699979268,\"side\":\"Sell\",\"size\":784},{\"symbol\":\"ETHUSD\",\"id\":29699979270,\"side\":\"Sell\",\"size\":1309},{\"symbol\":\"ETHUSD\",\"id\":29699979272,\"side\":\"Sell\",\"size\":280},{\"symbol\":\"ETHUSD\",\"id\":29699979275,\"side\":\"Sell\",\"size\":11461},{\"symbol\":\"ETHUSD\",\"id\":29699979281,\"side\":\"Sell\",\"size\":33},{\"symbol\":\"ETHUSD\",\"id\":29699979285,\"side\":\"Sell\",\"size\":33},{\"symbol\":\"ETHUSD\",\"id\":29699979286,\"side\":\"Sell\",\"size\":29},{\"symbol\":\"ETHUSD\",\"id\":29699979288,\"side\":\"Sell\",\"size\":28},{\"symbol\":\"ETHUSD\",\"id\":29699979289,\"side\":\"Sell\",\"size\":30},{\"symbol\":\"ETHUSD\",\"id\":29699979301,\"side\":\"Buy\",\"size\":9802},{\"symbol\":\"ETHUSD\",\"id\":29699979302,\"side\":\"Buy\",\"size\":9000},{\"symbol\":\"ETHUSD\",\"id\":29699979305,\"side\":\"Buy\",\"size\":8910},{\"symbol\":\"ETHUSD\",\"id\":29699979321,\"side\":\"Buy\",\"size\":50},{\"symbol\":\"ETHUSD\",\"id\":29699979322,\"side\":\"Buy\",\"size\":1072},{\"symbol\":\"ETHUSD\",\"id\":29699979324,\"side\":\"Buy\",\"size\":328},{\"symbol\":\"ETHUSD\",\"id\":29699979326,\"side\":\"Buy\",\"size\":348}]}","{\"table\":\"orderBookL2_25\",\"action\":\"insert\",\"data\":[{\"symbol\":\"ETHUSD\",\"id\":29699979259,\"side\":\"Sell\",\"size\":11,\"price\":1037.05},{\"symbol\":\"ETHUSD\",\"id\":29699979260,\"side\":\"Sell\",\"size\":301,\"price\":1037},{\"symbol\":\"ETHUSD\",\"id\":29699979262,\"side\":\"Sell\",\"size\":106,\"price\":1036.9}]}","{\"table\":\"orderBookL2_25\",\"action\":\"delete\",\"data\":[{\"symbol\":\"ETHUSD\",\"id\":29699979324,\"side\":\"Buy\"},{\"symbol\":\"ETHUSD\",\"id\":29699979325,\"side\":\"Buy\"},{\"symbol\":\"ETHUSD\",\"id\":29699979326,\"side\":\"Buy\"}]}","{\"table\":\"orderBookL2_25\",\"action\":\"update\",\"data\":[{\"symbol\":\"ETHUSD\",\"id\":29699979263,\"side\":\"Sell\",\"size\":2981},{\"symbol\":\"ETHUSD\",\"id\":29699979266,\"side\":\"Sell\",\"size\":178},{\"symbol\":\"ETHUSD\",\"id\":29699979270,\"side\":\"Sell\",\"size\":354},{\"symbol\":\"ETHUSD\",\"id\":29699979301,\"side\":\"Buy\",\"size\":7550},{\"symbol\":\"ETHUSD\",\"id\":29699979304,\"side\":\"Buy\",\"size\":11},{\"symbol\":\"ETHUSD\",\"id\":29699979305,\"side\":\"Buy\",\"size\":1910},{\"symbol\":\"ETHUSD\",\"id\":29699979310,\"side\":\"Buy\",\"size\":10033},{\"symbol\":\"ETHUSD\",\"id\":29699979317,\"side\":\"Buy\",\"size\":6698}]}","{\"table\":\"orderBookL2_25\",\"action\":\"insert\",\"data\":[{\"symbol\":\"ETHUSD\",\"id\":29699979296,\"side\":\"Buy\",\"size\":500,\"price\":1035.2},{\"symbol\":\"ETHUSD\",\"id\":29699979297,\"side\":\"Buy\",\"size\":7250,\"price\":1035.15},{\"symbol\":\"ETHUSD\",\"id\":29699979298,\"side\":\"Buy\",\"size\":9942,\"price\":1035.1}]}","{\"table\":\"orderBookL2_25\",\"action\":\"update\",\"data\":[{\"symbol\":\"ETHUSD\",\"id\":29699979317,\"side\":\"Buy\",\"size\":6976},{\"symbol\":\"ETHUSD\",\"id\":29699979319,\"side\":\"Buy\",\"size\":379}]}","{\"table\":\"orderBookL2_25\",\"action\":\"delete\",\"data\":[{\"symbol\":\"ETHUSD\",\"id\":29699979259,\"side\":\"Sell\"},{\"symbol\":\"ETHUSD\",\"id\":29699979303,\"side\":\"Buy\"}]}","{\"table\":\"orderBookL2_25\",\"action\":\"update\",\"data\":[{\"symbol\":\"ETHUSD\",\"id\":29699979296,\"side\":\"Buy\",\"size\":7500},{\"symbol\":\"ETHUSD\",\"id\":29699979297,\"side\":\"Buy\",\"size\":7000},{\"symbol\":\"ETHUSD\",\"id\":29699979305,\"side\":\"Buy\",\"size\":955},{\"symbol\":\"ETHUSD\",\"id\":29699979321,\"side\":\"Buy\",\"size\":173}]}","{\"table\":\"orderBookL2_25\",\"action\":\"insert\",\"data\":[{\"symbol\":\"ETHUSD\",\"id\":29699979278,\"side\":\"Sell\",\"size\":1819,\"price\":1036.1},{\"symbol\":\"ETHUSD\",\"id\":29699979295,\"side\":\"Buy\",\"size\":250,\"price\":1035.25}]}","{\"table\":\"orderBookL2_25\",\"action\":\"delete\",\"data\":[{\"symbol\":\"ETHUSD\",\"id\":29699979260,\"side\":\"Sell\"},{\"symbol\":\"ETHUSD\",\"id\":29699979262,\"side\":\"Sell\"},{\"symbol\":\"ETHUSD\",\"id\":29699979263,\"side\":\"Sell\"},{\"symbol\":\"ETHUSD\",\"id\":29699979265,\"side\":\"Sell\"},{\"symbol\":\"ETHUSD\",\"id\":29699979320,\"side\":\"Buy\"},{\"symbol\":\"ETHUSD\",\"id\":29699979321,\"side\":\"Buy\"},{\"symbol\":\"ETHUSD\",\"id\":29699979322,\"side\":\"Buy\"},{\"symbol\":\"ETHUSD\",\"id\":29699979323,\"side\":\"Buy\"}]}","{\"table\":\"orderBookL2_25\",\"action\":\"update\",\"data\":[{\"symbol\":\"ETHUSD\",\"id\":29699979272,\"side\":\"Sell\",\"size\":309},{\"symbol\":\"ETHUSD\",\"id\":29699979274,\"side\":\"Sell\",\"size\":206},{\"symbol\":\"ETHUSD\",\"id\":29699979275,\"side\":\"Sell\",\"size\":11492},{\"symbol\":\"ETHUSD\",\"id\":29699979276,\"side\":\"Sell\",\"size\":58},{\"symbol\":\"ETHUSD\",\"id\":29699979278,\"side\":\"Sell\",\"size\":1851},{\"symbol\":\"ETHUSD\",\"id\":29699979295,\"side\":\"Buy\",\"size\":7250},{\"symbol\":\"ETHUSD\",\"id\":29699979296,\"side\":\"Buy\",\"size\":7391},{\"symbol\":\"ETHUSD\",\"id\":29699979297,\"side\":\"Buy\",\"size\":7029},{\"symbol\":\"ETHUSD\",\"id\":29699979298,\"side\":\"Buy\",\"size\":9972},{\"symbol\":\"ETHUSD\",\"id\":29699979301,\"side\":\"Buy\",\"size\":7582},{\"symbol\":\"ETHUSD\",\"id\":29699979302,\"side\":\"Buy\",\"size\":2032},{\"symbol\":\"ETHUSD\",\"id\":29699979304,\"side\":\"Buy\",\"size\":42},{\"symbol\":\"ETHUSD\",\"id\":29699979305,\"side\":\"Buy\",\"size\":983},{\"symbol\":\"ETHUSD\",\"id\":29699979308,\"side\":\"Buy\",\"size\":80},{\"symbol\":\"ETHUSD\",\"id\":29699979309,\"side\":\"Buy\",\"size\":15078},{\"symbol\":\"ETHUSD\",\"id\":29699979310,\"side\":\"Buy\",\"size\":10083},{\"symbol\":\"ETHUSD\",\"id\":29699979311,\"side\":\"Buy\",\"size\":139},{\"symbol\":\"ETHUSD\",\"id\":29699979312,\"side\":\"Buy\",\"size\":83},{\"symbol\":\"ETHUSD\",\"id\":29699979313,\"side\":\"Buy\",\"size\":80},{\"symbol\":\"ETHUSD\",\"id\":29699979314,\"side\":\"Buy\",\"size\":78},{\"symbol\":\"ETHUSD\",\"id\":29699979315,\"side\":\"Buy\",\"size\":89},{\"symbol\":\"ETHUSD\",\"id\":29699979316,\"side\":\"Buy\",\"size\":84}]}","{\"table\":\"orderBookL2_25\",\"action\":\"insert\",\"data\":[{\"symbol\":\"ETHUSD\",\"id\":29699979273,\"side\":\"Sell\",\"size\":33,\"price\":1036.35},{\"symbol\":\"ETHUSD\",\"id\":29699979277,\"side\":\"Sell\",\"size\":32,\"price\":1036.15},{\"symbol\":\"ETHUSD\",\"id\":29699979279,\"side\":\"Sell\",\"size\":32,\"price\":1036.05},{\"symbol\":\"ETHUSD\",\"id\":29699979280,\"side\":\"Sell\",\"size\":34,\"price\":1036},{\"symbol\":\"ETHUSD\",\"id\":29699979299,\"side\":\"Buy\",\"size\":28,\"price\":1035.05},{\"symbol\":\"ETHUSD\",\"id\":29699979300,\"side\":\"Buy\",\"size\":228,\"price\":1035},{\"symbol\":\"ETHUSD\",\"id\":29699979303,\"side\":\"Buy\",\"size\":28,\"price\":1034.85},{\"symbol\":\"ETHUSD\",\"id\":29699979306,\"side\":\"Buy\",\"size\":30,\"price\":1034.7}]}","{\"table\":\"orderBookL2_25\",\"action\":\"delete\",\"data\":[{\"symbol\":\"ETHUSD\",\"id\":29699979290,\"side\":\"Sell\"},{\"symbol\":\"ETHUSD\",\"id\":29699979316,\"side\":\"Buy\"},{\"symbol\":\"ETHUSD\",\"id\":29699979317,\"side\":\"Buy\"},{\"symbol\":\"ETHUSD\",\"id\":29699979318,\"side\":\"Buy\"},{\"symbol\":\"ETHUSD\",\"id\":29699979319,\"side\":\"Buy\"}]}","{\"table\":\"orderBookL2_25\",\"action\":\"update\",\"data\":[{\"symbol\":\"ETHUSD\",\"id\":29699979275,\"side\":\"Sell\",\"size\":92},{\"symbol\":\"ETHUSD\",\"id\":29699979296,\"side\":\"Buy\",\"size\":391},{\"symbol\":\"ETHUSD\",\"id\":29699979297,\"side\":\"Buy\",\"size\":29},{\"symbol\":\"ETHUSD\",\"id\":29699979298,\"side\":\"Buy\",\"size\":2972},{\"symbol\":\"ETHUSD\",\"id\":29699979301,\"side\":\"Buy\",\"size\":82},{\"symbol\":\"ETHUSD\",\"id\":29699979302,\"side\":\"Buy\",\"size\":32},{\"symbol\":\"ETHUSD\",\"id\":29699979313,\"side\":\"Buy\",\"size\":8280}]}","{\"table\":\"orderBookL2_25\",\"action\":\"insert\",\"data\":[{\"symbol\":\"ETHUSD\",\"id\":29699979265,\"side\":\"Sell\",\"size\":836,\"price\":1036.75},{\"symbol\":\"ETHUSD\",\"id\":29699979291,\"side\":\"Buy\",\"size\":7500,\"price\":1035.45},{\"symbol\":\"ETHUSD\",\"id\":29699979292,\"side\":\"Buy\",\"size\":9000,\"price\":1035.4},{\"symbol\":\"ETHUSD\",\"id\":29699979293,\"side\":\"Buy\",\"size\":7000,\"price\":1035.35},{\"symbol\":\"ETHUSD\",\"id\":29699979294,\"side\":\"Buy\",\"size\":7000,\"price\":1035.3}]}","{\"table\":\"orderBookL2_25\",\"action\":\"delete\",\"data\":[{\"symbol\":\"ETHUSD\",\"id\":29699979315,\"side\":\"Buy\"}]}","{\"table\":\"orderBookL2_25\",\"action\":\"update\",\"data\":[{\"symbol\":\"ETHUSD\",\"id\":29699979295,\"side\":\"Buy\",\"size\":250},{\"symbol\":\"ETHUSD\",\"id\":29699979296,\"side\":\"Buy\",\"size\":261}]}","{\"table\":\"orderBookL2_25\",\"action\":\"insert\",\"data\":[{\"symbol\":\"ETHUSD\",\"id\":29699979290,\"side\":\"Buy\",\"size\":7500,\"price\":1035.5}]}","{\"table\":\"orderBookL2_25\",\"action\":\"update\",\"data\":[{\"symbol\":\"ETHUSD\",\"id\":29699979300,\"side\":\"Buy\",\"size\":28}]}","{\"table\":\"orderBookL2_25\",\"action\":\"update\",\"data\":[{\"symbol\":\"ETHUSD\",\"id\":29699979290,\"side\":\"Buy\",\"size\":7660},{\"symbol\":\"ETHUSD\",\"id\":29699979296,\"side\":\"Buy\",\"size\":31}]}","{\"table\":\"orderBookL2_25\",\"action\":\"delete\",\"data\":[{\"symbol\":\"ETHUSD\",\"id\":29699979288,\"side\":\"Sell\"},{\"symbol\":\"ETHUSD\",\"id\":29699979289,\"side\":\"Sell\"},{\"symbol\":\"ETHUSD\",\"id\":29699979295,\"side\":\"Buy\"}]}","{\"table\":\"orderBookL2_25\",\"action\":\"update\",\"data\":[{\"symbol\":\"ETHUSD\",\"id\":29699979269,\"side\":\"Sell\",\"size\":17},{\"symbol\":\"ETHUSD\",\"id\":29699979290,\"side\":\"Buy\",\"size\":7760},{\"symbol\":\"ETHUSD\",\"id\":29699979293,\"side\":\"Buy\",\"size\":7250},{\"symbol\":\"ETHUSD\",\"id\":29699979312,\"side\":\"Buy\",\"size\":50},{\"symbol\":\"ETHUSD\",\"id\":29699979313,\"side\":\"Buy\",\"size\":8250},{\"symbol\":\"ETHUSD\",\"id\":29699979314,\"side\":\"Buy\",\"size\":50}]}","{\"table\":\"orderBookL2_25\",\"action\":\"insert\",\"data\":[{\"symbol\":\"ETHUSD\",\"id\":29699979262,\"side\":\"Sell\",\"size\":11506,\"price\":1036.9},{\"symbol\":\"ETHUSD\",\"id\":29699979263,\"side\":\"Sell\",\"size\":2981,\"price\":1036.85},{\"symbol\":\"ETHUSD\",\"id\":29699979315,\"side\":\"Buy\",\"size\":61,\"price\":1034.25}]}","{\"table\":\"orderBookL2_25\",\"action\":\"delete\",\"data\":[{\"symbol\":\"ETHUSD\",\"id\":29699979287,\"side\":\"Sell\"}]}","{\"table\":\"orderBookL2_25\",\"action\":\"update\",\"data\":[{\"symbol\":\"ETHUSD\",\"id\":29699979265,\"side\":\"Sell\",\"size\":1169},{\"symbol\":\"ETHUSD\",\"id\":29699979270,\"side\":\"Sell\",\"size\":21},{\"symbol\":\"ETHUSD\",\"id\":29699979290,\"side\":\"Buy\",\"size\":8010},{\"symbol\":\"ETHUSD\",\"id\":29699979311,\"side\":\"Buy\",\"size\":110},{\"symbol\":\"ETHUSD\",\"id\":29699979312,\"side\":\"Buy\",\"size\":328}]}","{\"table\":\"orderBookL2_25\",\"action\":\"insert\",\"data\":[{\"symbol\":\"ETHUSD\",\"id\":29699979260,\"side\":\"Sell\",\"size\":301,\"price\":1037}]}","{\"table\":\"orderBookL2_25\",\"action\":\"delete\",\"data\":[{\"symbol\":\"ETHUSD\",\"id\":29699979285,\"side\":\"Sell\"},{\"symbol\":\"ETHUSD\",\"id\":29699979286,\"side\":\"Sell\"}]}","{\"table\":\"orderBookL2_25\",\"action\":\"update\",\"data\":[{\"symbol\":\"ETHUSD\",\"id\":29699979270,\"side\":\"Sell\",\"size\":81},{\"symbol\":\"ETHUSD\",\"id\":29699979278,\"side\":\"Sell\",\"size\":32},{\"symbol\":\"ETHUSD\",\"id\":29699979290,\"side\":\"Buy\",\"size\":8321},{\"symbol\":\"ETHUSD\",\"id\":29699979296,\"side\":\"Buy\",\"size\":15031},{\"symbol\":\"ETHUSD\",\"id\":29699979309,\"side\":\"Buy\",\"size\":78},{\"symbol\":\"ETHUSD\",\"id\":29699979310,\"side\":\"Buy\",\"size\":10050},{\"symbol\":\"ETHUSD\",\"id\":29699979311,\"side\":\"Buy\",\"size\":50},{\"symbol\":\"ETHUSD\",\"id\":29699979312,\"side\":\"Buy\",\"size\":606}]}","{\"table\":\"orderBookL2_25\",\"action\":\"insert\",\"data\":[{\"symbol\":\"ETHUSD\",\"id\":29699979255,\"side\":\"Sell\",\"size\":1366,\"price\":1037.25},{\"symbol\":\"ETHUSD\",\"id\":29699979259,\"side\":\"Sell\",\"size\":11,\"price\":1037.05}]}","{\"table\":\"orderBookL2_25\",\"action\":\"update\",\"data\":[{\"symbol\":\"ETHUSD\",\"id\":29699979290,\"side\":\"Buy\",\"size\":7860}]}","{\"table\":\"orderBookL2_25\",\"action\":\"update\",\"data\":[{\"symbol\":\"ETHUSD\",\"id\":29699979304,\"side\":\"Buy\",\"size\":997}]}","{\"table\":\"orderBookL2_25\",\"action\":\"delete\",\"data\":[{\"symbol\":\"ETHUSD\",\"id\":29699979294,\"side\":\"Buy\"}]}","{\"table\":\"orderBookL2_25\",\"action\":\"update\",\"data\":[{\"symbol\":\"ETHUSD\",\"id\":29699979290,\"side\":\"Buy\",\"size\":7891},{\"symbol\":\"ETHUSD\",\"id\":29699979291,\"side\":\"Buy\",\"size\":7000},{\"symbol\":\"ETHUSD\",\"id\":29699979302,\"side\":\"Buy\",\"size\":82},{\"symbol\":\"ETHUSD\",\"id\":29699979303,\"side\":\"Buy\",\"size\":78},{\"symbol\":\"ETHUSD\",\"id\":29699979304,\"side\":\"Buy\",\"size\":1047},{\"symbol\":\"ETHUSD\",\"id\":29699979305,\"side\":\"Buy\",\"size\":1033},{\"symbol\":\"ETHUSD\",\"id\":29699979306,\"side\":\"Buy\",\"size\":80},{\"symbol\":\"ETHUSD\",\"id\":29699979307,\"side\":\"Buy\",\"size\":81}]}","{\"table\":\"orderBookL2_25\",\"action\":\"insert\",\"data\":[{\"symbol\":\"ETHUSD\",\"id\":29699979289,\"side\":\"Buy\",\"size\":7500,\"price\":1035.55}]}","{\"table\":\"orderBookL2_25\",\"action\":\"delete\",\"data\":[{\"symbol\":\"ETHUSD\",\"id\":29699979314,\"side\":\"Buy\"},{\"symbol\":\"ETHUSD\",\"id\":29699979315,\"side\":\"Buy\"}]}","{\"table\":\"orderBookL2_25\",\"action\":\"update\",\"data\":[{\"symbol\":\"ETHUSD\",\"id\":29699979266,\"side\":\"Sell\",\"size\":55},{\"symbol\":\"ETHUSD\",\"id\":29699979270,\"side\":\"Sell\",\"size\":21},{\"symbol\":\"ETHUSD\",\"id\":29699979289,\"side\":\"Buy\",\"size\":7000},{\"symbol\":\"ETHUSD\",\"id\":29699979290,\"side\":\"Buy\",\"size\":7661},{\"symbol\":\"ETHUSD\",\"id\":29699979292,\"side\":\"Buy\",\"size\":2000},{\"symbol\":\"ETHUSD\",\"id\":29699979293,\"side\":\"Buy\",\"size\":250}]}","{\"table\":\"orderBookL2_25\",\"action\":\"insert\",\"data\":[{\"symbol\":\"ETHUSD\",\"id\":29699979287,\"side\":\"Buy\",\"size\":7500,\"price\":1035.65},{\"symbol\":\"ETHUSD\",\"id\":29699979288,\"side\":\"Buy\",\"size\":7000,\"price\":1035.6}]}","{\"table\":\"orderBookL2_25\",\"action\":\"delete\",\"data\":[{\"symbol\":\"ETHUSD\",\"id\":29699979291,\"side\":\"Buy\"}]}","{\"table\":\"orderBookL2_25\",\"action\":\"update\",\"data\":[{\"symbol\":\"ETHUSD\",\"id\":29699979290,\"side\":\"Buy\",\"size\":7461},{\"symbol\":\"ETHUSD\",\"id\":29699979307,\"side\":\"Buy\",\"size\":359},{\"symbol\":\"ETHUSD\",\"id\":29699979309,\"side\":\"Buy\",\"size\":375},{\"symbol\":\"ETHUSD\",\"id\":29699979312,\"side\":\"Buy\",\"size\":328}]}","{\"table\":\"orderBookL2_25\",\"action\":\"insert\",\"data\":[{\"symbol\":\"ETHUSD\",\"id\":29699979286,\"side\":\"Buy\",\"size\":7500,\"price\":1035.7}]}","{\"table\":\"orderBookL2_25\",\"action\":\"delete\",\"data\":[{\"symbol\":\"ETHUSD\",\"id\":29699979273,\"side\":\"Sell\"},{\"symbol\":\"ETHUSD\",\"id\":29699979277,\"side\":\"Sell\"},{\"symbol\":\"ETHUSD\",\"id\":29699979279,\"side\":\"Sell\"},{\"symbol\":\"ETHUSD\",\"id\":29699979280,\"side\":\"Sell\"},{\"symbol\":\"ETHUSD\",\"id\":29699979281,\"side\":\"Sell\"},{\"symbol\":\"ETHUSD\",\"id\":29699979282,\"side\":\"Sell\"},{\"symbol\":\"ETHUSD\",\"id\":29699979283,\"side\":\"Sell\"},{\"symbol\":\"ETHUSD\",\"id\":29699979284,\"side\":\"Sell\"}]}","{\"table\":\"orderBookL2_25\",\"action\":\"update\",\"data\":[{\"symbol\":\"ETHUSD\",\"id\":29699979272,\"side\":\"Sell\",\"size\":280},{\"symbol\":\"ETHUSD\",\"id\":29699979274,\"side\":\"Sell\",\"size\":174},{\"symbol\":\"ETHUSD\",\"id\":29699979275,\"side\":\"Sell\",\"size\":61},{\"symbol\":\"ETHUSD\",\"id\":29699979276,\"side\":\"Sell\",\"size\":25},{\"symbol\":\"ETHUSD\",\"id\":29699979278,\"side\":\"Sell\",\"size\":460},{\"symbol\":\"ETHUSD\",\"id\":29699979286,\"side\":\"Buy\",\"size\":7600},{\"symbol\":\"ETHUSD\",\"id\":29699979306,\"side\":\"Buy\",\"size\":50},{\"symbol\":\"ETHUSD\",\"id\":29699979307,\"side\":\"Buy\",\"size\":328},{\"symbol\":\"ETHUSD\",\"id\":29699979308,\"side\":\"Buy\",\"size\":50},{\"symbol\":\"ETHUSD\",\"id\":29699979309,\"side\":\"Buy\",\"size\":347}]}","{\"table\":\"orderBookL2_25\",\"action\":\"insert\",\"data\":[{\"symbol\":\"ETHUSD\",\"id\":29699979231,\"side\":\"Sell\",\"size\":30,\"price\":1038.45},{\"symbol\":\"ETHUSD\",\"id\":29699979236,\"side\":\"Sell\",\"size\":10000,\"price\":1038.2},{\"symbol\":\"ETHUSD\",\"id\":29699979237,\"side\":\"Sell\",\"size\":11,\"price\":1038.15},{\"symbol\":\"ETHUSD\",\"id\":29699979244,\"side\":\"Sell\",\"size\":7772,\"price\":1037.8},{\"symbol\":\"ETHUSD\",\"id\":29699979245,\"side\":\"Sell\",\"size\":3629,\"price\":1037.75},{\"symbol\":\"ETHUSD\",\"id\":29699979247,\"side\":\"Sell\",\"size\":7224,\"price\":1037.65},{\"symbol\":\"ETHUSD\",\"id\":29699979250,\"side\":\"Sell\",\"size\":395,\"price\":1037.5},{\"symbol\":\"ETHUSD\",\"id\":29699979252,\"side\":\"Sell\",\"size\":39,\"price\":1037.4}]}","{\"table\":\"orderBookL2_25\",\"action\":\"delete\",\"data\":[{\"symbol\":\"ETHUSD\",\"id\":29699979231,\"side\":\"Sell\"},{\"symbol\":\"ETHUSD\",\"id\":29699979236,\"side\":\"Sell\"},{\"symbol\":\"ETHUSD\",\"id\":29699979311,\"side\":\"Buy\"},{\"symbol\":\"ETHUSD\",\"id\":29699979312,\"side\":\"Buy\"},{\"symbol\":\"ETHUSD\",\"id\":29699979313,\"side\":\"Buy\"}]}","{\"table\":\"orderBookL2_25\",\"action\":\"update\",\"data\":[{\"symbol\":\"ETHUSD\",\"id\":29699979286,\"side\":\"Buy\",\"size\":7100},{\"symbol\":\"ETHUSD\",\"id\":29699979289,\"side\":\"Buy\",\"size\":61},{\"symbol\":\"ETHUSD\",\"id\":29699979290,\"side\":\"Buy\",\"size\":461}]}","{\"table\":\"orderBookL2_25\",\"action\":\"insert\",\"data\":[{\"symbol\":\"ETHUSD\",\"id\":29699979246,\"side\":\"Sell\",\"size\":332,\"price\":1037.7},{\"symbol\":\"ETHUSD\",\"id\":29699979279,\"side\":\"Sell\",\"size\":615,\"price\":1036.05},{\"symbol\":\"ETHUSD\",\"id\":29699979283,\"side\":\"Buy\",\"size\":250,\"price\":1035.85},{\"symbol\":\"ETHUSD\",\"id\":29699979284,\"side\":\"Buy\",\"size\":7500,\"price\":1035.8},{\"symbol\":\"ETHUSD\",\"id\":29699979285,\"side\":\"Buy\",\"size\":7250,\"price\":1035.75}]}","{\"table\":\"orderBookL2_25\",\"action\":\"delete\",\"data\":[{\"symbol\":\"ETHUSD\",\"id\":29699979288,\"side\":\"Buy\"},{\"symbol\":\"ETHUSD\",\"id\":29699979310,\"side\":\"Buy\"}]}","{\"table\":\"orderBookL2_25\",\"action\":\"update\",\"data\":[{\"symbol\":\"ETHUSD\",\"id\":29699979283,\"side\":\"Buy\",\"size\":7250},{\"symbol\":\"ETHUSD\",\"id\":29699979284,\"side\":\"Buy\",\"size\":7000},{\"symbol\":\"ETHUSD\",\"id\":29699979287,\"side\":\"Buy\",\"size\":500}]}","{\"table\":\"orderBookL2_25\",\"action\":\"insert\",\"data\":[{\"symbol\":\"ETHUSD\",\"id\":29699979281,\"side\":\"Buy\",\"size\":250,\"price\":1035.95},{\"symbol\":\"ETHUSD\",\"id\":29699979282,\"side\":\"Buy\",\"size\":7500,\"price\":1035.9}]}","{\"table\":\"orderBookL2_25\",\"action\":\"delete\",\"data\":[{\"symbol\":\"ETHUSD\",\"id\":29699979237,\"side\":\"Sell\"}]}","{\"table\":\"orderBookL2_25\",\"action\":\"update\",\"data\":[{\"symbol\":\"ETHUSD\",\"id\":29699979279,\"side\":\"Sell\",\"size\":715},{\"symbol\":\"ETHUSD\",\"id\":29699979281,\"side\":\"Buy\",\"size\":7250},{\"symbol\":\"ETHUSD\",\"id\":29699979282,\"side\":\"Buy\",\"size\":7000},{\"symbol\":\"ETHUSD\",\"id\":29699979286,\"side\":\"Buy\",\"size\":100},{\"symbol\":\"ETHUSD\",\"id\":29699979304,\"side\":\"Buy\",\"size\":92}]}","{\"table\":\"orderBookL2_25\",\"action\":\"insert\",\"data\":[{\"symbol\":\"ETHUSD\",\"id\":29699979277,\"side\":\"Sell\",\"size\":2000,\"price\":1036.15}]}","{\"table\":\"orderBookL2_25\",\"action\":\"delete\",\"data\":[{\"symbol\":\"ETHUSD\",\"id\":29699979286,\"side\":\"Buy\"}]}","{\"table\":\"orderBookL2_25\",\"action\":\"insert\",\"data\":[{\"symbol\":\"ETHUSD\",\"id\":29699979280,\"side\":\"Buy\",\"size\":500,\"price\":1036}]}","{\"table\":\"orderBookL2_25\",\"action\":\"update\",\"data\":[{\"symbol\":\"ETHUSD\",\"id\":29699979279,\"side\":\"Sell\",\"size\":100},{\"symbol\":\"ETHUSD\",\"id\":29699979280,\"side\":\"Buy\",\"size\":7500},{\"symbol\":\"ETHUSD\",\"id\":29699979285,\"side\":\"Buy\",\"size\":250}]}","{\"table\":\"orderBookL2_25\",\"action\":\"delete\",\"data\":[{\"symbol\":\"ETHUSD\",\"id\":29699979259,\"side\":\"Sell\"},{\"symbol\":\"ETHUSD\",\"id\":29699979277,\"side\":\"Sell\"},{\"symbol\":\"ETHUSD\",\"id\":29699979278,\"side\":\"Sell\"},{\"symbol\":\"ETHUSD\",\"id\":29699979279,\"side\":\"Sell\"},{\"symbol\":\"ETHUSD\",\"id\":29699979287,\"side\":\"Buy\"},{\"symbol\":\"ETHUSD\",\"id\":29699979290,\"side\":\"Buy\"},{\"symbol\":\"ETHUSD\",\"id\":29699979292,\"side\":\"Buy\"},{\"symbol\":\"ETHUSD\",\"id\":29699979293,\"side\":\"Buy\"}]}","{\"table\":\"orderBookL2_25\",\"action\":\"update\",\"data\":[{\"symbol\":\"ETHUSD\",\"id\":29699979244,\"side\":\"Sell\",\"size\":395},{\"symbol\":\"ETHUSD\",\"id\":29699979262,\"side\":\"Sell\",\"size\":106},{\"symbol\":\"ETHUSD\",\"id\":29699979263,\"side\":\"Sell\",\"size\":4},{\"symbol\":\"ETHUSD\",\"id\":29699979296,\"side\":\"Buy\",\"size\":15042},{\"symbol\":\"ETHUSD\",\"id\":29699979298,\"side\":\"Buy\",\"size\":8230},{\"symbol\":\"ETHUSD\",\"id\":29699979307,\"side\":\"Buy\",\"size\":50}]}","{\"table\":\"orderBookL2_25\",\"action\":\"insert\",\"data\":[{\"symbol\":\"ETHUSD\",\"id\":29699979231,\"side\":\"Sell\",\"size\":41,\"price\":1038.45},{\"symbol\":\"ETHUSD\",\"id\":29699979236,\"side\":\"Sell\",\"size\":10000,\"price\":1038.2},{\"symbol\":\"ETHUSD\",\"id\":29699979237,\"side\":\"Sell\",\"size\":11,\"price\":1038.15},{\"symbol\":\"ETHUSD\",\"id\":29699979256,\"side\":\"Sell\",\"size\":11400,\"price\":1037.2},{\"symbol\":\"ETHUSD\",\"id\":29699979310,\"side\":\"Buy\",\"size\":10050,\"price\":1034.5},{\"symbol\":\"ETHUSD\",\"id\":29699979311,\"side\":\"Buy\",\"size\":50,\"price\":1034.45},{\"symbol\":\"ETHUSD\",\"id\":29699979312,\"side\":\"Buy\",\"size\":328,\"price\":1034.4},{\"symbol\":\"ETHUSD\",\"id\":29699979313,\"side\":\"Buy\",\"size\":50,\"price\":1034.35}]}","{\"table\":\"orderBookL2_25\",\"action\":\"update\",\"data\":[{\"symbol\":\"ETHUSD\",\"id\":29699979269,\"side\":\"Sell\",\"size\":78},{\"symbol\":\"ETHUSD\",\"id\":29699979280,\"side\":\"Buy\",\"size\":9500},{\"symbol\":\"ETHUSD\",\"id\":29699979310,\"side\":\"Buy\",\"size\":50}]}","{\"table\":\"orderBookL2_25\",\"action\":\"delete\",\"data\":[{\"symbol\":\"ETHUSD\",\"id\":29699979284,\"side\":\"Buy\"},{\"symbol\":\"ETHUSD\",\"id\":29699979285,\"side\":\"Buy\"}]}","{\"table\":\"orderBookL2_25\",\"action\":\"update\",\"data\":[{\"symbol\":\"ETHUSD\",\"id\":29699979280,\"side\":\"Buy\",\"size\":9000},{\"symbol\":\"ETHUSD\",\"id\":29699979300,\"side\":\"Buy\",\"size\":10000},{\"symbol\":\"ETHUSD\",\"id\":29699979301,\"side\":\"Buy\",\"size\":50},{\"symbol\":\"ETHUSD\",\"id\":29699979302,\"side\":\"Buy\",\"size\":50},{\"symbol\":\"ETHUSD\",\"id\":29699979303,\"side\":\"Buy\",\"size\":50},{\"symbol\":\"ETHUSD\",\"id\":29699979304,\"side\":\"Buy\",\"size\":61},{\"symbol\":\"ETHUSD\",\"id\":29699979305,\"side\":\"Buy\",\"size\":1005},{\"symbol\":\"ETHUSD\",\"id\":29699979310,\"side\":\"Buy\",\"size\":347}]}","{\"table\":\"orderBookL2_25\",\"action\":\"insert\",\"data\":[{\"symbol\":\"ETHUSD\",\"id\":29699979278,\"side\":\"Buy\",\"size\":500,\"price\":1036.1},{\"symbol\":\"ETHUSD\",\"id\":29699979279,\"side\":\"Buy\",\"size\":7250,\"price\":1036.05}]}","{\"table\":\"orderBookL2_25\",\"action\":\"delete\",\"data\":[{\"symbol\":\"ETHUSD\",\"id\":29699979231,\"side\":\"Sell\"},{\"symbol\":\"ETHUSD\",\"id\":29699979236,\"side\":\"Sell\"},{\"symbol\":\"ETHUSD\",\"id\":29699979278,\"side\":\"Buy\"}]}","{\"table\":\"orderBookL2_25\",\"action\":\"update\",\"data\":[{\"symbol\":\"ETHUSD\",\"id\":29699979265,\"side\":\"Sell\",\"size\":836},{\"symbol\":\"ETHUSD\",\"id\":29699979281,\"side\":\"Buy\",\"size\":7000},{\"symbol\":\"ETHUSD\",\"id\":29699979282,\"side\":\"Buy\",\"size\":10065},{\"symbol\":\"ETHUSD\",\"id\":29699979283,\"side\":\"Buy\",\"size\":7000},{\"symbol\":\"ETHUSD\",\"id\":29699979300,\"side\":\"Buy\",\"size\":15194}]}","{\"table\":\"orderBookL2_25\",\"action\":\"insert\",\"data\":[{\"symbol\":\"ETHUSD\",\"id\":29699979249,\"side\":\"Sell\",\"size\":2779,\"price\":1037.55},{\"symbol\":\"ETHUSD\",\"id\":29699979258,\"side\":\"Sell\",\"size\":333,\"price\":1037.1},{\"symbol\":\"ETHUSD\",\"id\":29699979277,\"side\":\"Buy\",\"size\":250,\"price\":1036.15}]}","{\"table\":\"orderBookL2_25\",\"action\":\"update\",\"data\":[{\"symbol\":\"ETHUSD\",\"id\":29699979279,\"side\":\"Buy\",\"size\":7000},{\"symbol\":\"ETHUSD\",\"id\":29699979304,\"side\":\"Buy\",\"size\":339},{\"symbol\":\"ETHUSD\",\"id\":29699979309,\"side\":\"Buy\",\"size\":50}]}","{\"table\":\"orderBookL2_25\",\"action\":\"update\",\"data\":[{\"symbol\":\"ETHUSD\",\"id\":29699979304,\"side\":\"Buy\",\"size\":61}]}","{\"table\":\"orderBookL2_25\",\"action\":\"update\",\"data\":[{\"symbol\":\"ETHUSD\",\"id\":29699979277,\"side\":\"Buy\",\"size\":2250},{\"symbol\":\"ETHUSD\",\"id\":29699979280,\"side\":\"Buy\",\"size\":7000},{\"symbol\":\"ETHUSD\",\"id\":29699979311,\"side\":\"Buy\",\"size\":347}]}","{\"table\":\"orderBookL2_25\",\"action\":\"delete\",\"data\":[{\"symbol\":\"ETHUSD\",\"id\":29699979245,\"side\":\"Sell\"},{\"symbol\":\"ETHUSD\",\"id\":29699979247,\"side\":\"Sell\"}]}","{\"table\":\"orderBookL2_25\",\"action\":\"update\",\"data\":[{\"symbol\":\"ETHUSD\",\"id\":29699979277,\"side\":\"Buy\",\"size\":2750}]}","{\"table\":\"orderBookL2_25\",\"action\":\"insert\",\"data\":[{\"symbol\":\"ETHUSD\",\"id\":29699979231,\"side\":\"Sell\",\"size\":7370,\"price\":1038.45},{\"symbol\":\"ETHUSD\",\"id\":29699979236,\"side\":\"Sell\",\"size\":10000,\"price\":1038.2}]}","{\"table\":\"orderBookL2_25\",\"action\":\"delete\",\"data\":[{\"symbol\":\"ETHUSD\",\"id\":29699979231,\"side\":\"Sell\"},{\"symbol\":\"ETHUSD\",\"id\":29699979271,\"side\":\"Sell\"}]}","{\"table\":\"orderBookL2_25\",\"action\":\"update\",\"data\":[{\"symbol\":\"ETHUSD\",\"id\":29699979269,\"side\":\"Sell\",\"size\":17},{\"symbol\":\"ETHUSD\",\"id\":29699979304,\"side\":\"Buy\",\"size\":339},{\"symbol\":\"ETHUSD\",\"id\":29699979305,\"side\":\"Buy\",\"size\":1283},{\"symbol\":\"ETHUSD\",\"id\":29699979311,\"side\":\"Buy\",\"size\":50},{\"symbol\":\"ETHUSD\",\"id\":29699979312,\"side\":\"Buy\",\"size\":50}]}","{\"table\":\"orderBookL2_25\",\"action\":\"insert\",\"data\":[{\"symbol\":\"ETHUSD\",\"id\":29699979238,\"side\":\"Sell\",\"size\":7224,\"price\":1038.1},{\"symbol\":\"ETHUSD\",\"id\":29699979247,\"side\":\"Sell\",\"size\":11,\"price\":1037.65}]}","{\"table\":\"orderBookL2_25\",\"action\":\"delete\",\"data\":[{\"symbol\":\"ETHUSD\",\"id\":29699979276,\"side\":\"Sell\"}]}","{\"table\":\"orderBookL2_25\",\"action\":\"update\",\"data\":[{\"symbol\":\"ETHUSD\",\"id\":29699979277,\"side\":\"Buy\",\"size\":3230},{\"symbol\":\"ETHUSD\",\"id\":29699979311,\"side\":\"Buy\",\"size\":10050}]}","{\"table\":\"orderBookL2_25\",\"action\":\"insert\",\"data\":[{\"symbol\":\"ETHUSD\",\"id\":29699979231,\"side\":\"Sell\",\"size\":7370,\"price\":1038.45}]}"]